<?xml version="1.0" ?>
<!-- =================================================================================== -->
<!-- |    This document was autogenerated by xacro from astribot_s1_whole_body_without_wheel.xacro | -->
<!-- |    EDITING THIS FILE BY HAND IS NOT RECOMMENDED                                 | -->
<!-- =================================================================================== -->
<!-- run: xacro astribot_s1_whole_body.xacro -o astribot_s1_whole_body.urdf to generate the following .urdf file -->
<robot name="astribot_whole_body">
  <link name="astribot_torso_base">
    <inertial>
      <origin rpy="0 0 0" xyz="-0.062784 0.007017 0.035375"/>
      <mass value="39.24781"/>
      <inertia ixx="1.071997" ixy="0.015889" ixz="-0.058447" iyy="1.218431" iyz="-0.002015" izz="1.489411"/>
    </inertial>
    <visual>
      <origin rpy="1.5708 0 0" xyz="0 0 0"/>
      <geometry>
        <mesh filename="meshes/dae/astribot_torso_base.dae"/>
      </geometry>
    </visual>
    <collision>
      <origin rpy="0 0 0" xyz="0 0 -0.05"/>
      <geometry>
        <cylinder length="0.1" radius="0.3"/>
      </geometry>
    </collision>
  </link>
  <link name="astribot_torso_link_1">
    <inertial>
      <origin rpy="0 0 0" xyz="-0.15249 0.00021066 -0.0033476"/>
      <mass value="7.3766"/>
      <inertia ixx="0.028834" ixy="-0.0052759" ixz="0.00010767" iyy="0.1483" iyz="1.1652E-05" izz="0.14268"/>
    </inertial>
    <visual>
      <origin rpy="1.5708 0 0" xyz="0 0 0"/>
      <geometry>
        <mesh filename="meshes/dae/astribot_torso_link_1.dae"/>
      </geometry>
    </visual>
    <collision>
      <origin rpy="0 1.57 0" xyz="-0.15 0 0"/>
      <geometry>
        <cylinder length="0.3" radius="0.1"/>
      </geometry>
    </collision>
  </link>
  <joint name="astribot_torso_joint_1" type="revolute">
    <origin rpy="-1.5708 1.5708 0" xyz="0 0 0.12"/>
    <parent link="astribot_torso_base"/>
    <child link="astribot_torso_link_1"/>
    <axis xyz="0 0 1"/>
    <limit effort="100" lower="-0.04" upper="1.3" velocity="1.8"/>
  </joint>
  <link name="astribot_torso_link_2">
    <inertial>
      <origin rpy="0 0 0" xyz="-0.22214 0.028873 0.00059024"/>
      <mass value="5.6183"/>
      <inertia ixx="0.0082545" ixy="0.0011523" ixz="0.00035614" iyy="0.012677" iyz="-5.8287E-05" izz="0.017512"/>
    </inertial>
    <visual>
      <origin rpy="1.5708 0 0" xyz="0 0 0"/>
      <geometry>
        <mesh filename="meshes/dae/astribot_torso_link_2.dae"/>
      </geometry>
    </visual>
    <collision>
      <origin rpy="0 1.57 -0.25" xyz="-0.15 0.03 0"/>
      <geometry>
        <cylinder length="0.3" radius="0.1"/>
      </geometry>
    </collision>
  </link>
  <joint name="astribot_torso_joint_2" type="revolute">
    <origin rpy="0 0 0" xyz="-0.38 0 0"/>
    <parent link="astribot_torso_link_1"/>
    <child link="astribot_torso_link_2"/>
    <axis xyz="0 0 1"/>
    <limit effort="100" lower="-2.3" upper="0.06" velocity="1.8"/>
  </joint>
  <link name="astribot_torso_link_3">
    <inertial>
      <origin rpy="0 0 0" xyz="-0.017519 0.00059523 0.00025821"/>
      <mass value="0.49013"/>
      <inertia ixx="0.00022212" ixy="-2.6767E-07" ixz="4.3987E-07" iyy="0.00036522" iyz="3.8834E-07" izz="0.00038039"/>
    </inertial>
    <visual>
      <origin rpy="0 0 0" xyz="0 0 0"/>
      <geometry>
        <mesh filename="meshes/s1_torso/astribot_torso_link_3.STL"/>
      </geometry>
      <material name="">
        <color rgba="0.922 0.929 0.941 1"/>
      </material>
    </visual>
    <collision>
      <origin rpy="0 1.57 0" xyz="-0.18 0.01 0"/>
      <geometry>
        <cylinder length="0.35" radius="0.09"/>
      </geometry>
    </collision>
  </link>
  <joint name="astribot_torso_joint_3" type="revolute">
    <origin rpy="0 0 0" xyz="-0.390 0 0"/>
    <parent link="astribot_torso_link_2"/>
    <child link="astribot_torso_link_3"/>
    <axis xyz="0 0 1"/>
    <limit effort="100" lower="-0.4" upper="2.3" velocity="1.8"/>
  </joint>
  <link name="astribot_torso_link_4">
    <inertial>
      <origin rpy="0 0 0" xyz="0.00476227191516749 -4.56966810241128E-05 0.242912573510671"/>
      <mass value="3.55695635704638"/>
      <inertia ixx="0.0165768322563514" ixy="-9.94098112646385E-06" ixz="-0.000100011483384926" iyy="0.014904355097835" iyz="9.86752047032885E-07" izz="0.0110629318711333"/>
    </inertial>
    <visual>
      <origin rpy="1.5708 0 0" xyz="0 0 0"/>
      <geometry>
        <mesh filename="meshes/dae/astribot_torso_link_4.dae"/>
      </geometry>
    </visual>
  </link>
  <joint name="astribot_torso_joint_4" type="revolute">
    <origin rpy="1.5708 0 -1.5708" xyz="0 0 0"/>
    <parent link="astribot_torso_link_3"/>
    <child link="astribot_torso_link_4"/>
    <axis xyz="0 0 1"/>
    <limit effort="100" lower="-1.2" upper="1.2" velocity="1.8"/>
  </joint>

  <link name="astribot_torso_end_effector">
    <inertial>
      <origin rpy="0 0 0" xyz="0 0 0"/>
      <mass value="0"/>
      <inertia ixx="0" ixy="0" ixz="0" iyy="0" iyz="0" izz="0"/>
    </inertial>
  </link>
  <joint name="astribot_torso_end_effector_fixed_joint" type="fixed">
    <origin rpy="0.0 0.0 0.0" xyz="0 0 0.34475"/>
    <parent link="astribot_torso_link_4"/>
    <child link="astribot_torso_end_effector"/>
  </joint>
  
  <link name="astribot_head_base_link">
    <inertial>
      <origin rpy="0 0 0" xyz="-0.02816247 -0.00023176 -0.05211965"/>
      <mass value="0.39541440"/>
      <inertia ixx="0.00036025" ixy="-0.00003505" ixz="0.00004865" iyy="0.00049377" iyz="0.00000243" izz="0.00074441"/>
    </inertial>
    <visual>
      <origin rpy="0 0 0" xyz="0 0 0"/>
      <geometry>
        <mesh filename="meshes/s1_head/astribot_head_base_link.STL"/>
      </geometry>
      <material name="">
        <color rgba="0.098 0.098 0.110 1"/>
      </material>
    </visual>
  </link>
  <link name="astribot_head_link_1">
    <inertial>
      <origin rpy="0 0 0" xyz="0.00003191 -0.00038566 -0.02579910"/>
      <mass value="0.13910581"/>
      <inertia ixx="0.00004567" ixy="0.00000003" ixz="0.00000004" iyy="0.00004789" iyz="-0.00000091" izz="0.00003779"/>
    </inertial>
    <visual>
      <origin rpy="0 0 0" xyz="0 0 0"/>
      <geometry>
        <mesh filename="meshes/s1_head/astribot_head_link_1.STL"/>
      </geometry>
      <material name="">
        <color rgba="0.216 0.216 0.235 1"/>
      </material>
    </visual>
  </link>
  <joint name="astribot_head_joint_1" type="revolute">
    <origin rpy="0 0 0" xyz="0 0 0"/>
    <parent link="astribot_head_base_link"/>
    <child link="astribot_head_link_1"/>
    <axis xyz="0 0 1"/>
    <limit effort="100" lower="-1.57" upper="1.57" velocity="4.0"/>
  </joint>
  <link name="astribot_head_link_2">
    <inertial>
      <origin rpy="0 0 0" xyz="0.00705824 -0.14472601 -0.00061724"/>
      <mass value="0.97012447"/>
      <inertia ixx="0.00555660" ixy="-0.00041600" ixz="-0.00000036" iyy="0.00151908" iyz="-0.00012043" izz="0.00544493"/>
    </inertial>
    <visual>
      <origin rpy="1.5708 0 0" xyz="0 0 0"/>
      <geometry>
        <mesh filename="meshes/dae/astribot_head_link_2.dae"/>
      </geometry>
    </visual>
    <collision>
      <origin rpy="0 0 0" xyz="0 -0.15 0"/>
      <geometry>
        <sphere radius="0.11"/>
      </geometry>
    </collision>
  </link>
  <joint name="astribot_head_joint_2" type="revolute">
    <origin rpy="-1.5708 0 0" xyz="0 0 0"/>
    <parent link="astribot_head_link_1"/>
    <child link="astribot_head_link_2"/>
    <axis xyz="0 0 1"/>
    <limit effort="100" lower="-1.22" upper="1.22" velocity="4.0"/>
  </joint>


  <link name="astribot_arm_left_base_link">
    <inertial>
      <origin rpy="0 0 0" xyz="-0.04309067 -0.01849796 -0.01384838"/>
      <mass value="2.22887320"/>
      <inertia ixx="0.00386389" ixy="-0.00050396" ixz="0.00025566" iyy="0.00306042" iyz="0.00019224" izz="0.00570294"/>
    </inertial>
    <visual>
      <origin rpy="0 0 0" xyz="0 0 0"/>
      <geometry>
        <mesh filename="meshes/s1_arm/astribot_arm_left_base_link.STL"/>
      </geometry>
      <material name="">
        <color rgba="0.922 0.929 0.941 1"/>
      </material>
    </visual>
  </link>
  <link name="astribot_arm_left_link_1">
    <inertial>
      <origin rpy="0 0 0" xyz="0.00012026 0.00047499 -0.05682561"/>
      <mass value="0.59936716"/>
      <inertia ixx="0.00064791" ixy="0.00000149" ixz="0.00000133" iyy="0.00065264" iyz="0.00000160" izz="0.00050137"/>
    </inertial>
    <visual>
      <origin rpy="0 0 0" xyz="0 0 0"/>
      <geometry>
        <mesh filename="meshes/s1_arm/astribot_arm_link_1.STL"/>
      </geometry>
      <material name="">
        <color rgba="0.922 0.929 0.941 1"/>
      </material>
    </visual>
  </link>
  <joint name="astribot_arm_left_joint_1" type="revolute">
    <origin rpy="0 0 0" xyz="0 0 0.091"/>
    <parent link="astribot_arm_left_base_link"/>
    <child link="astribot_arm_left_link_1"/>
    <axis xyz="0 0 1"/>
    <limit effort="265" lower="-3.1" upper="3.1" velocity="8.4"/>
  </joint>
  <link name="astribot_arm_left_link_2">
    <inertial>
      <origin rpy="0 0 0" xyz="-0.00396228 0.03490708 0.04270156"/>
      <mass value="1.43694657"/>
      <inertia ixx="0.00360751" ixy="-0.00009193" ixz="0.00007764" iyy="0.00283747" iyz="0.00054945" izz="0.00172927"/>
    </inertial>
    <visual>
      <origin rpy="0 0 0" xyz="0 0 0"/>
      <geometry>
        <mesh filename="meshes/s1_arm/astribot_arm_left_link_2.STL"/>
      </geometry>
      <material name="">
        <color rgba="0.922 0.929 0.941 1"/>
      </material>
    </visual>
  </link>
  <joint name="astribot_arm_left_joint_2" type="revolute">
    <origin rpy="1.5708 0 0" xyz="0 0 0"/>
    <parent link="astribot_arm_left_link_1"/>
    <child link="astribot_arm_left_link_2"/>
    <axis xyz="0 0 1"/>
    <limit effort="265" lower="-1.53" upper="0.46" velocity="8.4"/>
  </joint>
  <link name="astribot_arm_left_link_3">
    <inertial>
      <origin rpy="0 0 0" xyz="0.00531263 0.00020707 0.16136713"/>
      <mass value="2.0926399"/>
      <inertia ixx="0.01752179" ixy="2.336e-05" ixz="0.00144018" iyy="0.01784671" iyz="-3.027e-05" izz="0.0021843"/>
    </inertial>
    <visual>
      <origin rpy="0 0 0" xyz="0 0 0"/>
      <geometry>
        <mesh filename="meshes/s1_arm/astribot_arm_link_3.STL"/>
      </geometry>
      <material name="">
        <color rgba="0.922 0.929 0.941 1"/>
      </material>
    </visual>
    <collision>
      <origin rpy="0 0 0" xyz="0 0 0.15"/>
      <geometry>
        <cylinder length="0.18" radius="0.05"/>
      </geometry>
    </collision>
  </link>
  <joint name="astribot_arm_left_joint_3" type="revolute">
    <origin rpy="1.5708 0 -1.5708" xyz="0 0.05 0"/>
    <parent link="astribot_arm_left_link_2"/>
    <child link="astribot_arm_left_link_3"/>
    <axis xyz="0 0 1"/>
    <limit effort="132" lower="-3.1" upper="3.1" velocity="8.4"/>
  </joint>
  <link name="astribot_arm_left_link_4">
    <inertial>
      <origin rpy="0 0 0" xyz="0.00017294 -0.01269315 0.00196140"/>
      <mass value="0.36587933"/>
      <inertia ixx="0.00047693" ixy="0.00000635" ixz=" 0.00000135" iyy="0.00036801" iyz="0.00000705" izz="0.00050082"/>
    </inertial>
    <visual>
      <origin rpy="0 0 0" xyz="0 0 0"/>
      <geometry>
        <mesh filename="meshes/s1_arm/astribot_arm_link_4.STL"/>
      </geometry>
      <material name="">
        <color rgba="0.922 0.929 0.941 1"/>
      </material>
    </visual>
    <collision>
      <origin rpy="0 0 0" xyz="0 0 0"/>
      <geometry>
        <sphere radius="0.06"/>
      </geometry>
    </collision>
  </link>
  <joint name="astribot_arm_left_joint_4" type="revolute">
    <origin rpy="-1.5708 0 0" xyz="0.03 0 0.309"/>
    <parent link="astribot_arm_left_link_3"/>
    <child link="astribot_arm_left_link_4"/>
    <axis xyz="0 0 1"/>
    <limit effort="142" lower="-0.06" upper="2.61" velocity="15"/>
  </joint>
  <link name="astribot_arm_left_link_5">
    <inertial>
      <origin rpy="0 0 0" xyz="-0.00032037 -0.00015185 0.15370447"/>
      <mass value="1.24085064"/>
      <inertia ixx="0.00454092" ixy="1.58e-06" ixz="-5.91e-06" iyy="0.00438922" iyz="-4.927e-05" izz="0.00079442"/>
    </inertial>
    <visual>
      <origin rpy="0 0 0" xyz="0 0 0"/>
      <geometry>
        <mesh filename="meshes/s1_arm/astribot_arm_link_5.STL"/>
      </geometry>
      <material name="">
        <color rgba="0.922 0.929 0.941 1"/>
      </material>
    </visual>
    <collision>
      <origin rpy="0 0 0" xyz="0 0 0.14"/>
      <geometry>
        <cylinder length="0.14" radius="0.05"/>
      </geometry>
    </collision>
  </link>
  <joint name="astribot_arm_left_joint_5" type="revolute">
    <origin rpy="1.5708 0 0" xyz="0 0 0"/>
    <parent link="astribot_arm_left_link_4"/>
    <child link="astribot_arm_left_link_5"/>
    <axis xyz="0 0 1"/>
    <limit effort="71" lower="-2.56" upper="2.56" velocity="20"/>
  </joint>
  <link name="astribot_arm_left_link_6">
    <inertial>
      <origin rpy="0 0 0" xyz="-0.00010311 0.00001218 0.00013181"/>
      <mass value="0.22465307"/>
      <inertia ixx="0.00016474" ixy="0.00000007" ixz="0.00000025" iyy="0.00015608" iyz="0.00000018" izz="0.00008555"/>
    </inertial>
    <visual>
      <origin rpy="0 0 0" xyz="0 0 0"/>
      <geometry>
        <mesh filename="meshes/s1_arm/astribot_arm_link_6.STL"/>
      </geometry>
      <material name="">
        <color rgba="0.922 0.929 0.941 1"/>
      </material>
    </visual>
  </link>
  <joint name="astribot_arm_left_joint_6" type="revolute">
    <origin rpy="-1.5708 0 0" xyz="0 0 0.277"/>
    <parent link="astribot_arm_left_link_5"/>
    <child link="astribot_arm_left_link_6"/>
    <axis xyz="0 0 1"/>
    <limit effort="20" lower="-0.76" upper="0.76" velocity="16.8"/>
  </joint>
  <link name="astribot_arm_left_link_7">
    <inertial>
      <origin rpy="0 0 0" xyz="4.333e-05 -0.00723447 -0.00362428"/>
      <mass value="0.12772019"/>
      <inertia ixx="0.00013672" ixy="1.6e-07" ixz="-2.4e-07" iyy="0.00010783" iyz="-3.35e-06" izz="5.858e-05"/>
    </inertial>
    <visual>
      <origin rpy="0 0 0" xyz="0 0 0"/>
      <geometry>
        <mesh filename="meshes/s1_arm/astribot_arm_link_7.STL"/>
      </geometry>
      <material name="">
        <color rgba="0.922 0.929 0.941 1"/>
      </material>
    </visual>
    <collision>
      <origin rpy="0 0 0" xyz="0.006 0 0"/>
      <geometry>
        <sphere radius="0.05"/>
      </geometry>
    </collision>
  </link>
  <joint name="astribot_arm_left_joint_7" type="revolute">
    <origin rpy="0 1.5708 0" xyz="0 0 0"/>
    <parent link="astribot_arm_left_link_6"/>
    <child link="astribot_arm_left_link_7"/>
    <axis xyz="0 0 1"/>
    <limit effort="20" lower="-1.53" upper="1.53" velocity="16.8"/>
  </joint>



   <!-- 创建夹爪基座 -->
    <link name="astribot_gripper_left_base">
        <inertial>
            <origin xyz="0.000286114278273852 5.46143913165315E-05 0.0313070801272036" rpy="0 0 0" />
            <mass value="0.187915151353017" />
            <inertia
              ixx="7.7083129306073E-05"
              ixy="-5.2914269679694E-08"
              ixz="-7.97668331424419E-07"
              iyy="9.20833968358638E-05"
              iyz="2.05531866691208E-06"
              izz="0.000110550450454867" />
        </inertial>
        <visual>
            <origin xyz="0 0 0" rpy="0 0 0"/>
            <geometry>
                <mesh filename="meshes/s1_gripper/astribot_gripper_base_link.STL"/>
            </geometry>
            <material name="">
                <color rgba="0.922 0.929 0.941 1"/>
            </material>
        </visual>
    </link>
    <joint name="astribot_gripper_left_arm_joint" type="fixed">
        <origin xyz="0 -0.045 0" rpy="1.5708 0 0"/>
        <parent link="astribot_arm_left_link_7"/>
        <child link="astribot_gripper_left_base"/>
    </joint>

    <!-- 创建夹爪左侧 L1 -->
    <link name="astribot_gripper_left_Link_L1">
        <inertial>
            <origin xyz="0.0238640864176069 9.47687805681264E-11 0.0229075443586857" rpy="0 0 0" />
            <mass value="0.0132773347208514" />
            <inertia
              ixx="4.28423784706423E-06"
              ixy="-3.1809828478112E-14"
              ixz="-1.80523452558963E-06"
              iyy="3.7385709458377E-06"
              iyz="-1.72714143575754E-14"
              izz="4.66371355874453E-06" />
        </inertial>
        <visual>
            <origin xyz="0 0 0" rpy="0 0 0"/>
            <geometry>
                <!-- <mesh filename="meshes/s1_gripper/astribot_gripper_L1_Link.STL"/> -->
                <mesh filename="meshes/dae/astribot_gripper_L1_Link.dae"/> 
            </geometry>
        </visual>
    </link>
    <joint name="astribot_gripper_left_joint_L1" type="revolute">
        <origin xyz="0.0145 0 0.0510999999999999" rpy="0 0 0" />
        <parent link="astribot_gripper_left_base"/>
        <child link="astribot_gripper_left_Link_L1"/>
        <axis xyz="0 1 0" />
        <limit lower="-1.57" upper="1.57" effort="1" velocity="1" />
        <disable_collisions>true</disable_collisions>
    </joint>

    <!-- 创建夹爪左侧 L2 -->
    <link name="astribot_gripper_left_Link_L2">
        <inertial>
            <origin xyz="0.0140847588556024 1.38103934445237E-10 0.0136360450679544" rpy="0 0 0" />
            <mass value="0.0225788543528282" />
            <inertia
              ixx="4.05677771144473E-06"
              ixy="9.09979590001103E-14"
              ixz="-3.87016503842647E-06"
              iyy="9.27580355823765E-06"
              iyz="2.24851503246122E-15"
              izz="7.45268797104849E-06" />
        </inertial>
        <visual>
            <origin xyz="0 0 0" rpy="0 0 0"/>
            <geometry>
                <!-- <mesh filename="meshes/s1_gripper/astribot_gripper_L2_Link.STL"/> -->
                <mesh filename="meshes/dae/astribot_gripper_L2_Link.dae"/> 
            </geometry>
        </visual>
    </link>
    <joint name="astribot_gripper_left_joint_L2" type="revolute">
        <origin xyz="0.0325 0 0.0510999999999999" rpy="0 0 0" />
        <parent link="astribot_gripper_left_base"/>
        <child link="astribot_gripper_left_Link_L2"/>
        <axis xyz="0 1 0"/>
        <limit lower="-1.57" upper="1.57" effort="1" velocity="1" />
        <disable_collisions>true</disable_collisions>
    </joint>

    <!-- 创建夹爪左侧 L11 -->
    <link name="astribot_gripper_left_Link_L11">
        <inertial>
            <origin xyz="0.00580213800883548 -8.25165165519234E-05 0.0308700387872591" rpy="0 0 0" />
            <mass value="0.048314774841657" />
            <inertia
              ixx="1.32981890600081E-05"
              ixy="-5.57022585371537E-10"
              ixz="7.4802436798051E-07"
              iyy="1.22071199015097E-05"
              iyz="-5.96543860568114E-08"
              izz="3.57131660356933E-06" />
    </inertial>
        <visual>
            <origin xyz="0 0 0" rpy="0 0 0"/>
            <geometry>
                <!-- <mesh filename="meshes/s1_gripper/astribot_gripper_L11_Link.STL"/> -->
                <mesh filename="meshes/dae/astribot_gripper_L11_Link.dae"/> 
            </geometry>
        </visual>
        <collision>
            <origin xyz="0 0 0" rpy="0 0 0"/>
            <geometry>
                <!-- <mesh filename="meshes/s1_gripper/astribot_gripper_L11_Link.STL"/> -->
                <mesh filename="meshes/dae/astribot_gripper_L11_Link.dae"/> 
            </geometry>
        </collision>
    </link>
    <joint name="astribot_gripper_left_joint_L11" type="revolute">
        <origin xyz="0.0412500000000001 0 0.036379080527138" rpy="0 0 0" />
        <parent link="astribot_gripper_left_Link_L1"/>
        <child link="astribot_gripper_left_Link_L11"/>
        <axis xyz="0 1 0"/>
        <limit effort="1" velocity="1" lower="-1.57" upper="1.57"/>
        <disable_collisions>true</disable_collisions>
    </joint>

    <!-- 创建夹爪右侧 R1 -->
    <link name="astribot_gripper_left_Link_R1">
        <inertial>
            <origin xyz="-0.0238640864176057 -9.47685705791467E-11 0.0229075443586915" rpy="0 0 0" />
            <mass value="0.0132773347208514" />
            <inertia
              ixx="4.28423784706424E-06"
              ixy="-3.18098256836165E-14"
              ixz="1.80523452558963E-06"
              iyy="3.7385709458377E-06"
              iyz="1.727141962837E-14"
              izz="4.66371355874451E-06" />
        </inertial>
        <visual>
            <origin xyz="0 0 0" rpy="0 0 0"/>
            <geometry>
                <!-- <mesh filename="meshes/s1_gripper/astribot_gripper_R1_Link.STL"/> -->
                <mesh filename="meshes/dae/astribot_gripper_R1_Link.dae"/> 
            </geometry>
        </visual>
    </link>
    <joint name="astribot_gripper_left_joint_R1" type="revolute">
        <origin xyz="-0.0144999999999999 0 0.0510999999999939" rpy="0 0 0" />
        <parent link="astribot_gripper_left_base"/>
        <child link="astribot_gripper_left_Link_R1"/>
        <axis xyz="0 1 0" />
        <limit lower="-1.57" upper="1.57" effort="1" velocity="1" />
        <disable_collisions>true</disable_collisions>
    </joint>

    <!-- 创建夹爪右侧 R2 -->
    <link name="astribot_gripper_left_Link_R2">
        <inertial>
            <origin xyz="-0.0140847588556023 -1.38096956088557E-10 0.0136360450679544" rpy="0 0 0" />
            <mass value="0.0225788543528282" />
            <inertia
              ixx="4.05677771144474E-06"
              ixy="9.09979616664103E-14"
              ixz="3.87016503842647E-06"
              iyy="9.27580355823765E-06"
              iyz="-2.24851632164595E-15"
              izz="7.45268797104847E-06" />
            
        </inertial>
        <visual>
            <origin xyz="0 0 0" rpy="0 0 0"/>
            <geometry>
                <!-- <mesh filename="meshes/s1_gripper/astribot_gripper_R2_Link.STL"/> -->
                <mesh filename="meshes/dae/astribot_gripper_R2_Link.dae"/> 
            </geometry>
        </visual>
    </link>
    <joint name="astribot_gripper_left_joint_R2" type="revolute">
        <origin xyz="-0.0325 0 0.0510999999999999" rpy="0 0 0" />
        <parent link="astribot_gripper_left_base"/>
        <child link="astribot_gripper_left_Link_R2"/>
        <axis xyz="0 1 0" />
        <limit lower="-1.57" upper="1.57" effort="1" velocity="1" />
        <disable_collisions>true</disable_collisions>
    </joint>

    <!-- 创建夹爪右侧 R11 -->
    <link name="astribot_gripper_left_Link_R11">
        <inertial>
            <origin xyz="-0.00580213801042903 8.25165349425033E-05 0.0308700387923378" rpy="0 0 0" />
            <mass value="0.048314774834573" />
            <inertia
              ixx="1.32981890422821E-05"
              ixy="-5.57024612407707E-10"
              ixz="-7.48024369000206E-07"
              iyy="1.22071198991499E-05"
              iyz="5.96543919268235E-08"
              izz="3.57131658810875E-06" />

        </inertial>
        <visual>
            <origin xyz="0 0 0" rpy="0 0 0"/>
            <geometry>
                <!-- <mesh filename="meshes/s1_gripper/astribot_gripper_R11_Link.STL"/> -->
                <mesh filename="meshes/dae/astribot_gripper_R11_Link.dae"/>
            </geometry>
        </visual>
        <collision>
            <origin xyz="0 0 0" rpy="0 0 0"/>
            <geometry>
                <!-- <mesh filename="meshes/s1_gripper/astribot_gripper_R11_Link.STL"/> -->
                 <mesh filename="meshes/dae/astribot_gripper_R11_Link.dae"/>
            </geometry>
        </collision>
    </link>
    <joint name="astribot_gripper_left_joint_R11" type="revolute">
        <origin xyz="-0.0412499999999999 0 0.0363790805271382" rpy="0 0 0" />
        <parent link="astribot_gripper_left_Link_R1" />
        <child link="astribot_gripper_left_Link_R11" />
        <axis xyz="0 1 0" /> 
        <limit lower="-1.57" upper="1.57" effort="1" velocity="1" />
        <!-- <mimic joint="astribot_gripper_left_joint_L11" multiplier="-1.0" offset="0.0" /> -->
        <disable_collisions>true</disable_collisions>
    </joint>





  <link name="astribot_arm_right_base_link">
    <inertial>
      <origin rpy="0 0 0" xyz="-0.04450932 0.01988693 0.00162589"/>
      <mass value="2.22887320"/>
      <inertia ixx="0.00396811" ixy="0.00041290" ixz="-0.00033387" iyy="0.00304615" iyz="-0.00021572" izz="0.00574641"/>
    </inertial>
    <visual>
      <origin rpy="0 0 0" xyz="0 0 0"/>
      <geometry>
        <mesh filename="meshes/s1_arm/astribot_arm_right_base_link.STL"/>
      </geometry>
      <material name="">
        <color rgba="0.922 0.929 0.941 1"/>
      </material>
    </visual>
  </link>
  <link name="astribot_arm_right_link_1">
    <inertial>
      <origin rpy="0 0 0" xyz="0.00012026 0.00047499 -0.05682561"/>
      <mass value="0.59936716"/>
      <inertia ixx="0.00064791" ixy="0.00000149" ixz="0.00000133" iyy="0.00065264" iyz="0.00000160" izz="0.00050137"/>
    </inertial>
    <visual>
      <origin rpy="0 0 0" xyz="0 0 0"/>
      <geometry>
        <mesh filename="meshes/s1_arm/astribot_arm_link_1.STL"/>
      </geometry>
      <material name="">
        <color rgba="0.922 0.929 0.941 1"/>
      </material>
    </visual>
  </link>
  <joint name="astribot_arm_right_joint_1" type="revolute">
    <origin rpy="0 0 0" xyz="0 0 0.091"/>
    <parent link="astribot_arm_right_base_link"/>
    <child link="astribot_arm_right_link_1"/>
    <axis xyz="0 0 1"/>
    <limit effort="265" lower="-3.1" upper="3.1" velocity="8.4"/>
  </joint>
  <link name="astribot_arm_right_link_2">
    <inertial>
      <origin rpy="0 0 0" xyz="-0.00384709 0.03502105 -0.04050705"/>
      <mass value="1.45811037"/>
      <inertia ixx="0.00394196" ixy="-8.846e-05" ixz="-3.742e-05" iyy="0.00316298" iyz="-0.0007079" izz="0.00177295"/>
    </inertial>
    <visual>
      <origin rpy="0 0 0" xyz="0 0 0"/>
      <geometry>
        <mesh filename="meshes/s1_arm/astribot_arm_right_link_2.STL"/>
      </geometry>
      <material name="">
        <color rgba="0.922 0.929 0.941 1"/>
      </material>
    </visual>
  </link>
  <joint name="astribot_arm_right_joint_2" type="revolute">
    <origin rpy="1.5708 0 0" xyz="0 0 0"/>
    <parent link="astribot_arm_right_link_1"/>
    <child link="astribot_arm_right_link_2"/>
    <axis xyz="0 0 1"/>
    <limit effort="265" lower="-1.53" upper="0.46" velocity="8.4"/>
  </joint>
  <link name="astribot_arm_right_link_3">
    <inertial>
      <origin rpy="0 0 0" xyz="0.00531263 0.00020707 0.16136713"/>
      <mass value="2.0926399"/>
      <inertia ixx="0.01752179" ixy="2.336e-05" ixz="0.00144018" iyy="0.01784671" iyz="-3.027e-05" izz="0.0021843"/>
    </inertial>
    <visual>
      <origin rpy="0 0 0" xyz="0 0 0"/>
      <geometry>
        <mesh filename="meshes/s1_arm/astribot_arm_link_3.STL"/>
      </geometry>
      <material name="">
        <color rgba="0.922 0.929 0.941 1"/>
      </material>
    </visual>
    <collision>
      <origin rpy="0 0 0" xyz="0 0 0.15"/>
      <geometry>
        <cylinder length="0.18" radius="0.05"/>
      </geometry>
    </collision>
  </link>
  <joint name="astribot_arm_right_joint_3" type="revolute">
    <origin rpy="1.5708 0 -1.5708" xyz="0 0.05 0"/>
    <parent link="astribot_arm_right_link_2"/>
    <child link="astribot_arm_right_link_3"/>
    <axis xyz="0 0 1"/>
    <limit effort="132" lower="-3.1" upper="3.1" velocity="8.4"/>
  </joint>
  <link name="astribot_arm_right_link_4">
    <inertial>
      <origin rpy="0 0 0" xyz="0.00017294 -0.01269315 0.00196140"/>
      <mass value="0.36587933"/>
      <inertia ixx="0.00047693" ixy="0.00000635" ixz=" 0.00000135" iyy="0.00036801" iyz="0.00000705" izz="0.00050082"/>
    </inertial>
    <visual>
      <origin rpy="0 0 0" xyz="0 0 0"/>
      <geometry>
        <mesh filename="meshes/s1_arm/astribot_arm_link_4.STL"/>
      </geometry>
      <material name="">
        <color rgba="0.922 0.929 0.941 1"/>
      </material>
    </visual>
    <collision>
      <origin rpy="0 0 0" xyz="0 0 0"/>
      <geometry>
        <sphere radius="0.06"/>
      </geometry>
    </collision>
  </link>
  <joint name="astribot_arm_right_joint_4" type="revolute">
    <origin rpy="-1.5708 0 0" xyz="0.03 0 0.309"/>
    <parent link="astribot_arm_right_link_3"/>
    <child link="astribot_arm_right_link_4"/>
    <axis xyz="0 0 1"/>
    <limit effort="142" lower="-0.06" upper="2.61" velocity="15"/>
  </joint>
  <link name="astribot_arm_right_link_5">
    <inertial>
      <origin rpy="0 0 0" xyz="-0.00032037 -0.00015185 0.15370447"/>
      <mass value="1.24085064"/>
      <inertia ixx="0.00454092" ixy="1.58e-06" ixz="-5.91e-06" iyy="0.00438922" iyz="-4.927e-05" izz="0.00079442"/>
    </inertial>
    <visual>
      <origin rpy="0 0 0" xyz="0 0 0"/>
      <geometry>
        <mesh filename="meshes/s1_arm/astribot_arm_link_5.STL"/>
      </geometry>
      <material name="">
        <color rgba="0.922 0.929 0.941 1"/>
      </material>
    </visual>
    <collision>
      <origin rpy="0 0 0" xyz="0 0 0.14"/>
      <geometry>
        <cylinder length="0.14" radius="0.05"/>
      </geometry>
    </collision>
  </link>
  <joint name="astribot_arm_right_joint_5" type="revolute">
    <origin rpy="1.5708 0 0" xyz="0 0 0"/>
    <parent link="astribot_arm_right_link_4"/>
    <child link="astribot_arm_right_link_5"/>
    <axis xyz="0 0 1"/>
    <limit effort="71" lower="-2.56" upper="2.56" velocity="20"/>
  </joint>
  <link name="astribot_arm_right_link_6">
    <inertial>
      <origin rpy="0 0 0" xyz="-0.00010311 0.00001218 0.00013181"/>
      <mass value="0.22465307"/>
      <inertia ixx="0.00016474" ixy="0.00000007" ixz="0.00000025" iyy="0.00015608" iyz="0.00000018" izz="0.00008555"/>
    </inertial>
    <visual>
      <origin rpy="0 0 0" xyz="0 0 0"/>
      <geometry>
        <mesh filename="meshes/s1_arm/astribot_arm_link_6.STL"/>
      </geometry>
      <material name="">
        <color rgba="0.922 0.929 0.941 1"/>
      </material>
    </visual>
  </link>
  <joint name="astribot_arm_right_joint_6" type="revolute">
    <origin rpy="-1.5708 0 0" xyz="0 0 0.277"/>
    <parent link="astribot_arm_right_link_5"/>
    <child link="astribot_arm_right_link_6"/>
    <axis xyz="0 0 1"/>
    <limit effort="20" lower="-0.76" upper="0.76" velocity="16.8"/>
  </joint>
  <link name="astribot_arm_right_link_7">
    <inertial>
      <origin rpy="0 0 0" xyz="4.333e-05 -0.00723447 -0.00362428"/>
      <mass value="0.12772019"/>
      <inertia ixx="0.00013672" ixy="1.6e-07" ixz="-2.4e-07" iyy="0.00010783" iyz="-3.35e-06" izz="5.858e-05"/>
    </inertial>
    <visual>
      <origin rpy="0 0 0" xyz="0 0 0"/>
      <geometry>
        <mesh filename="meshes/s1_arm/astribot_arm_link_7.STL"/>
      </geometry>
      <material name="">
        <color rgba="0.922 0.929 0.941 1"/>
      </material>
    </visual>
    <collision>
      <origin rpy="0 0 0" xyz="0.006 0 0"/>
      <geometry>
        <sphere radius="0.05"/>
      </geometry>
    </collision>
  </link>
  <joint name="astribot_arm_right_joint_7" type="revolute">
    <origin rpy="0 1.5708 0" xyz="0 0 0"/>
    <parent link="astribot_arm_right_link_6"/>
    <child link="astribot_arm_right_link_7"/>
    <axis xyz="0 0 1"/>
    <limit effort="20" lower="-1.53" upper="1.53" velocity="16.8"/>
  </joint>
 
   <!-- 创建夹爪基座 -->
    <link name="astribot_gripper_right_base">
        <inertial>
            <origin xyz="0.000286114278273852 5.46143913165315E-05 0.0313070801272036" rpy="0 0 0" />
            <mass value="0.187915151353017" />
            <inertia
              ixx="7.7083129306073E-05"
              ixy="-5.2914269679694E-08"
              ixz="-7.97668331424419E-07"
              iyy="9.20833968358638E-05"
              iyz="2.05531866691208E-06"
              izz="0.000110550450454867" />
        </inertial>
        <visual>
            <origin xyz="0 0 0" rpy="0 0 0"/>
            <geometry>
                <mesh filename="meshes/s1_gripper/astribot_gripper_base_link.STL"/>
            </geometry>
            <material name="">
                <color rgba="0.922 0.929 0.941 1"/>
            </material>
        </visual>
    </link>
    <joint name="astribot_gripper_right_arm_joint" type="fixed">
        <origin xyz="0 -0.045 0" rpy="1.5708 0 0"/>
        <parent link="astribot_arm_right_link_7"/>
        <child link="astribot_gripper_right_base"/>
    </joint>

    <!-- 创建夹爪左侧 L1 -->
    <link name="astribot_gripper_right_Link_L1">
        <inertial>
            <origin xyz="0.0238640864176069 9.47687805681264E-11 0.0229075443586857" rpy="0 0 0" />
            <mass value="0.0132773347208514" />
            <inertia
              ixx="4.28423784706423E-06"
              ixy="-3.1809828478112E-14"
              ixz="-1.80523452558963E-06"
              iyy="3.7385709458377E-06"
              iyz="-1.72714143575754E-14"
              izz="4.66371355874453E-06" />
        </inertial>
        <visual>
            <origin xyz="0 0 0" rpy="0 0 0"/>
            <geometry>
                <!-- <mesh filename="meshes/s1_gripper/astribot_gripper_L1_Link.STL"/> -->
                <mesh filename="meshes/dae/astribot_gripper_L1_Link.dae"/>
            </geometry>
        </visual>
    </link>
    <joint name="astribot_gripper_right_joint_L1" type="revolute">
        <origin xyz="0.0145 0 0.0510999999999999" rpy="0 0 0" />
        <parent link="astribot_gripper_right_base"/>
        <child link="astribot_gripper_right_Link_L1"/>
        <axis xyz="0 1 0" />
        <limit lower="-1.57" upper="1.57" effort="1" velocity="1" />
        <disable_collisions>true</disable_collisions>
    </joint>

    <!-- 创建夹爪左侧 L2 -->
    <link name="astribot_gripper_right_Link_L2">
        <inertial>
            <origin xyz="0.0140847588556024 1.38103934445237E-10 0.0136360450679544" rpy="0 0 0" />
            <mass value="0.0225788543528282" />
            <inertia
              ixx="4.05677771144473E-06"
              ixy="9.09979590001103E-14"
              ixz="-3.87016503842647E-06"
              iyy="9.27580355823765E-06"
              iyz="2.24851503246122E-15"
              izz="7.45268797104849E-06" />
        </inertial>
        <visual>
            <origin xyz="0 0 0" rpy="0 0 0"/>
            <geometry>
                <!-- <mesh filename="meshes/s1_gripper/astribot_gripper_L2_Link.STL"/> -->
                 <mesh filename="meshes/dae/astribot_gripper_L2_Link.dae"/>
            </geometry>
        </visual>
    </link>
    <joint name="astribot_gripper_right_joint_L2" type="revolute">
        <origin xyz="0.0325 0 0.0510999999999999" rpy="0 0 0" />
        <parent link="astribot_gripper_right_base"/>
        <child link="astribot_gripper_right_Link_L2"/>
        <axis xyz="0 1 0"/>
        <limit lower="-1.57" upper="1.57" effort="1" velocity="1" />
        <disable_collisions>true</disable_collisions>
    </joint>

    <!-- 创建夹爪左侧 L11 -->
    <link name="astribot_gripper_right_Link_L11">
        <inertial>
            <origin xyz="0.00580213800883548 -8.25165165519234E-05 0.0308700387872591" rpy="0 0 0" />
            <mass value="0.048314774841657" />
            <inertia
              ixx="1.32981890600081E-05"
              ixy="-5.57022585371537E-10"
              ixz="7.4802436798051E-07"
              iyy="1.22071199015097E-05"
              iyz="-5.96543860568114E-08"
              izz="3.57131660356933E-06" />
    </inertial>
        <visual>
            <origin xyz="0 0 0" rpy="0 0 0"/>
            <geometry>
                <!-- <mesh filename="meshes/s1_gripper/astribot_gripper_L11_Link.STL"/> -->
                 <mesh filename="meshes/dae/astribot_gripper_L11_Link.dae"/>
            </geometry>
        </visual>
        <collision>
            <origin xyz="0 0 0" rpy="0 0 0"/>
            <geometry>
                <!-- <mesh filename="meshes/s1_gripper/astribot_gripper_L11_Link.STL"/> -->
                <mesh filename="meshes/dae/astribot_gripper_L11_Link.dae"/>
            </geometry>
        </collision>
    </link>
    <joint name="astribot_gripper_right_joint_L11" type="revolute">
        <origin xyz="0.0412500000000001 0 0.036379080527138" rpy="0 0 0" />
        <parent link="astribot_gripper_right_Link_L1"/>
        <child link="astribot_gripper_right_Link_L11"/>
        <axis xyz="0 1 0"/>
        <limit effort="1" velocity="1" lower="-1.57" upper="1.57"/>
        <disable_collisions>true</disable_collisions>
    </joint>

    <!-- 创建夹爪右侧 R1 -->
    <link name="astribot_gripper_right_Link_R1">
        <inertial>
            <origin xyz="-0.0238640864176057 -9.47685705791467E-11 0.0229075443586915" rpy="0 0 0" />
            <mass value="0.0132773347208514" />
            <inertia
              ixx="4.28423784706424E-06"
              ixy="-3.18098256836165E-14"
              ixz="1.80523452558963E-06"
              iyy="3.7385709458377E-06"
              iyz="1.727141962837E-14"
              izz="4.66371355874451E-06" />
        </inertial>
        <visual>
            <origin xyz="0 0 0" rpy="0 0 0"/>
            <geometry>
                <!-- <mesh filename="meshes/s1_gripper/astribot_gripper_R1_Link.STL"/> -->
                <mesh filename="meshes/dae/astribot_gripper_R1_Link.dae"/>
            </geometry>
        </visual>
    </link>
    <joint name="astribot_gripper_right_joint_R1" type="revolute">
        <origin xyz="-0.0144999999999999 0 0.0510999999999939" rpy="0 0 0" />
        <parent link="astribot_gripper_right_base"/>
        <child link="astribot_gripper_right_Link_R1"/>
        <axis xyz="0 1 0" />
        <limit lower="-1.57" upper="1.57" effort="1" velocity="1" />
        <disable_collisions>true</disable_collisions>
    </joint>

    <!-- 创建夹爪右侧 R2 -->
    <link name="astribot_gripper_right_Link_R2">
        <inertial>
            <origin xyz="-0.0140847588556023 -1.38096956088557E-10 0.0136360450679544" rpy="0 0 0" />
            <mass value="0.0225788543528282" />
            <inertia
              ixx="4.05677771144474E-06"
              ixy="9.09979616664103E-14"
              ixz="3.87016503842647E-06"
              iyy="9.27580355823765E-06"
              iyz="-2.24851632164595E-15"
              izz="7.45268797104847E-06" />
            
        </inertial>
        <visual>
            <origin xyz="0 0 0" rpy="0 0 0"/>
            <geometry>
                <!-- <mesh filename="meshes/s1_gripper/astribot_gripper_R2_Link.STL"/> -->
                <mesh filename="meshes/dae/astribot_gripper_R2_Link.dae"/>
            </geometry>
        </visual>
    </link>
    <joint name="astribot_gripper_right_joint_R2" type="revolute">
        <origin xyz="-0.0325 0 0.0510999999999999" rpy="0 0 0" />
        <parent link="astribot_gripper_right_base"/>
        <child link="astribot_gripper_right_Link_R2"/>
        <axis xyz="0 1 0" />
        <limit lower="-1.57" upper="1.57" effort="1" velocity="1" />
        <disable_collisions>true</disable_collisions>
    </joint>

    <!-- 创建夹爪右侧 R11 -->
    <link name="astribot_gripper_right_Link_R11">
        <inertial>
            <origin xyz="-0.00580213801042903 8.25165349425033E-05 0.0308700387923378" rpy="0 0 0" />
            <mass value="0.048314774834573" />
            <inertia
              ixx="1.32981890422821E-05"
              ixy="-5.57024612407707E-10"
              ixz="-7.48024369000206E-07"
              iyy="1.22071198991499E-05"
              iyz="5.96543919268235E-08"
              izz="3.57131658810875E-06" />

        </inertial>
        <visual>
            <origin xyz="0 0 0" rpy="0 0 0"/>
            <geometry>
                <!-- <mesh filename="meshes/s1_gripper/astribot_gripper_R11_Link.STL"/> -->
                <mesh filename="meshes/dae/astribot_gripper_R11_Link.dae"/>
            </geometry>
        </visual>
        <collision>
            <origin xyz="0 0 0" rpy="0 0 0"/>
            <geometry>
                <!-- <mesh filename="meshes/s1_gripper/astribot_gripper_R11_Link.STL"/> -->
                <mesh filename="meshes/dae/astribot_gripper_R11_Link.dae"/>
            </geometry>
        </collision>
    </link>
    <joint name="astribot_gripper_right_joint_R11" type="revolute">
        <origin xyz="-0.0412499999999999 0 0.0363790805271382" rpy="0 0 0" />
        <parent link="astribot_gripper_right_Link_R1" />
        <child link="astribot_gripper_right_Link_R11" />
        <axis xyz="0 1 0" /> 
        <limit lower="-1.57" upper="1.57" effort="1" velocity="1" />
        <!-- <mimic joint="astribot_gripper_left_joint_L11" multiplier="-1.0" offset="0.0" /> -->
        <disable_collisions>true</disable_collisions>
    </joint>


  <joint name="astribot_head_fixed_joint" type="fixed">
    <parent link="astribot_torso_end_effector"/>
    <child link="astribot_head_base_link"/>
    <origin rpy="0 0 0" xyz="0 0 0.1229"/>
  </joint>
  <joint name="astribot_arm_left_base_fixed_joint" type="fixed">
    <parent link="astribot_torso_end_effector"/>
    <child link="astribot_arm_left_base_link"/>
    <origin rpy="0 -1.22173 -1.5707963" xyz="0 0.06449 0.02348"/>
  </joint>
  <joint name="astribot_arm_right_base_fixed_joint" type="fixed">
    <parent link="astribot_torso_end_effector"/>
    <child link="astribot_arm_right_base_link"/>
    <origin rpy="0 -1.22173 1.5707963" xyz="0 -0.06449 0.02348"/>
  </joint>
  
</robot>
